Workbook

Sheet ภาพรวม
A1: Project Tracking — ทีมการตลาดดิจิทัล (ข้อมูลตัวอย่าง)
A2: วันที่ตรวจสอบ | B2: =TODAY() -> 46324
A4: งานทั้งหมด | B4: งานเสร็จแล้ว | C4: อัตราความสำเร็จ | D4: งานเกินกำหนด | E4: ชั่วโมงประเมินรวม | F4: ชั่วโมงใช้จริงรวม
A5: =COUNTA(งานทั้งหมด!$A$5:$A$300) -> 46 | B5: =COUNTIF(งานทั้งหมด!$F$5:$F$300,"เสร็จแล้ว") -> 14 | C5: =IFERROR(B5/A5,0) -> 0.30434783 | D5: =COUNTIF(งานทั้งหมด!$M$5:$M$300,"เกินกำหนด") -> 5 | E5: =SUM(งานทั้งหมด!$I$5:$I$300) -> 567 | F5: =SUM(งานทั้งหมด!$J$5:$J$300) -> 329
A7: สรุปรายบุคคล
A8: ผู้รับผิดชอบ | B8: ตำแหน่ง | C8: งานทั้งหมด | D8: ยังไม่เริ่ม | E8: กำลังดำเนินการ | F8: รอตรวจ | G8: เสร็จแล้ว | H8: เกินกำหนด | I8: ชั่วโมงประเมิน | J8: ชั่วโมงจริง | K8: % เสร็จ | L8: ประเมิน ÷ จริง
A9: =ทีมงาน!B5 -> วิภา | B9: =ทีมงาน!C5 -> หัวหน้าทีม (Team Lead) | C9: =COUNTIF(งานทั้งหมด!$D$5:$D$300,A9) -> 5 | D9: =COUNTIFS(งานทั้งหมด!$D$5:$D$300,A9,งานทั้งหมด!$F$5:$F$300,"ยังไม่เริ่ม") -> 1 | E9: =COUNTIFS(งานทั้งหมด!$D$5:$D$300,A9,งานทั้งหมด!$F$5:$F$300,"กำลังดำเนินการ") -> 2 | F9: =COUNTIFS(งานทั้งหมด!$D$5:$D$300,A9,งานทั้งหมด!$F$5:$F$300,"รอตรวจ") -> 1 | G9: =COUNTIFS(งานทั้งหมด!$D$5:$D$300,A9,งานทั้งหมด!$F$5:$F$300,"เสร็จแล้ว") -> 1 | H9: =COUNTIFS(งานทั้งหมด!$D$5:$D$300,A9,งานทั้งหมด!$M$5:$M$300,"เกินกำหนด") -> 0 | I9: =SUMIF(งานทั้งหมด!$D$5:$D$300,A9,งานทั้งหมด!$I$5:$I$300) -> 64 | J9: =SUMIF(งานทั้งหมด!$D$5:$D$300,A9,งานทั้งหมด!$J$5:$J$300) -> 39 | K9: =IFERROR(G9/C9,0) -> 0.2 | L9: =IFERROR(I9/J9,0) -> 1.6410256
A10: =ทีมงาน!B6 -> ณัฐวุฒิ | B10: =ทีมงาน!C6 -> Senior Graphic Designer | C10: =COUNTIF(งานทั้งหมด!$D$5:$D$300,A10) -> 5 | D10: =COUNTIFS(งานทั้งหมด!$D$5:$D$300,A10,งานทั้งหมด!$F$5:$F$300,"ยังไม่เริ่ม") -> 1 | E10: =COUNTIFS(งานทั้งหมด!$D$5:$D$300,A10,งานทั้งหมด!$F$5:$F$300,"กำลังดำเนินการ") -> 2 | F10: =COUNTIFS(งานทั้งหมด!$D$5:$D$300,A10,งานทั้งหมด!$F$5:$F$300,"รอตรวจ") -> 1 | G10: =COUNTIFS(งานทั้งหมด!$D$5:$D$300,A10,งานทั้งหมด!$F$5:$F$300,"เสร็จแล้ว") -> 1 | H10: =COUNTIFS(งานทั้งหมด!$D$5:$D$300,A10,งานทั้งหมด!$M$5:$M$300,"เกินกำหนด") -> 1 | I10: =SUMIF(งานทั้งหมด!$D$5:$D$300,A10,งานทั้งหมด!$I$5:$I$300) -> 58 | J10: =SUMIF(งานทั้งหมด!$D$5:$D$300,A10,งานทั้งหมด!$J$5:$J$300) -> 41 | K10: =IFERROR(G10/C10,0) -> 0.2 | L10: =IFERROR(I10/J10,0) -> 1.4146341
A11: =ทีมงาน!B7 -> นภา | B11: =ทีมงาน!C7 -> Content Writer | C11: =COUNTIF(งานทั้งหมด!$D$5:$D$300,A11) -> 5 | D11: =COUNTIFS(งานทั้งหมด!$D$5:$D$300,A11,งานทั้งหมด!$F$5:$F$300,"ยังไม่เริ่ม") -> 1 | E11: =COUNTIFS(งานทั้งหมด!$D$5:$D$300,A11,งานทั้งหมด!$F$5:$F$300,"กำลังดำเนินการ") -> 2 | F11: =COUNTIFS(งานทั้งหมด!$D$5:$D$300,A11,งานทั้งหมด!$F$5:$F$300,"รอตรวจ") -> 0 | G11: =COUNTIFS(งานทั้งหมด!$D$5:$D$300,A11,งานทั้งหมด!$F$5:$F$300,"เสร็จแล้ว") -> 2 | H11: =COUNTIFS(งานทั้งหมด!$D$5:$D$300,A11,งานทั้งหมด!$M$5:$M$300,"เกินกำหนด") -> 0 | I11: =SUMIF(งานทั้งหมด!$D$5:$D$300,A11,งานทั้งหมด!$I$5:$I$300) -> 86 | J11: =SUMIF(งานทั้งหมด!$D$5:$D$300,A11,งานทั้งหมด!$J$5:$J$300) -> 48 | K11: =IFERROR(G11/C11,0) -> 0.4 | L11: =IFERROR(I11/J11,0) -> 1.7916667
A12: =ทีมงาน!B8 -> ปิยะ | B12: =ทีมงาน!C8 -> Photographer & Video Producer | C12: =COUNTIF(งานทั้งหมด!$D$5:$D$300,A12) -> 6 | D12: =COUNTIFS(งานทั้งหมด!$D$5:$D$300,A12,งานทั้งหมด!$F$5:$F$300,"ยังไม่เริ่ม") -> 2 | E12: =COUNTIFS(งานทั้งหมด!$D$5:$D$300,A12,งานทั้งหมด!$F$5:$F$300,"กำลังดำเนินการ") -> 1 | F12: =COUNTIFS(งานทั้งหมด!$D$5:$D$300,A12,งานทั้งหมด!$F$5:$F$300,"รอตรวจ") -> 0 | G12: =COUNTIFS(งานทั้งหมด!$D$5:$D$300,A12,งานทั้งหมด!$F$5:$F$300,"เสร็จแล้ว") -> 3 | H12: =COUNTIFS(งานทั้งหมด!$D$5:$D$300,A12,งานทั้งหมด!$M$5:$M$300,"เกินกำหนด") -> 1 | I12: =SUMIF(งานทั้งหมด!$D$5:$D$300,A12,งานทั้งหมด!$I$5:$I$300) -> 62 | J12: =SUMIF(งานทั้งหมด!$D$5:$D$300,A12,งานทั้งหมด!$J$5:$J$300) -> 45 | K12: =IFERROR(G12/C12,0) -> 0.5 | L12: =IFERROR(I12/J12,0) -> 1.3777778
A13: =ทีมงาน!B9 -> ธนพล | B13: =ทีมงาน!C9 -> Performance Marketer | C13: =COUNTIF(งานทั้งหมด!$D$5:$D$300,A13) -> 5 | D13: =COUNTIFS(งานทั้งหมด!$D$5:$D$300,A13,งานทั้งหมด!$F$5:$F$300,"ยังไม่เริ่ม") -> 2 | E13: =COUNTIFS(งานทั้งหมด!$D$5:$D$300,A13,งานทั้งหมด!$F$5:$F$300,"กำลังดำเนินการ") -> 2 | F13: =COUNTIFS(งานทั้งหมด!$D$5:$D$300,A13,งานทั้งหมด!$F$5:$F$300,"รอตรวจ") -> 0 | G13: =COUNTIFS(งานทั้งหมด!$D$5:$D$300,A13,งานทั้งหมด!$F$5:$F$300,"เสร็จแล้ว") -> 1 | H13: =COUNTIFS(งานทั้งหมด!$D$5:$D$300,A13,งานทั้งหมด!$M$5:$M$300,"เกินกำหนด") -> 1 | I13: =SUMIF(งานทั้งหมด!$D$5:$D$300,A13,งานทั้งหมด!$I$5:$I$300) -> 39 | J13: =SUMIF(งานทั้งหมด!$D$5:$D$300,A13,งานทั้งหมด!$J$5:$J$300) -> 12 | K13: =IFERROR(G13/C13,0) -> 0.2 | L13: =IFERROR(I13/J13,0) -> 3.25
A14: =ทีมงาน!B10 -> ศุภกิจ | B14: =ทีมงาน!C10 -> Web Developer | C14: =COUNTIF(งานทั้งหมด!$D$5:$D$300,A14) -> 4 | D14: =COUNTIFS(งานทั้งหมด!$D$5:$D$300,A14,งานทั้งหมด!$F$5:$F$300,"ยังไม่เริ่ม") -> 2 | E14: =COUNTIFS(งานทั้งหมด!$D$5:$D$300,A14,งานทั้งหมด!$F$5:$F$300,"กำลังดำเนินการ") -> 1 | F14: =COUNTIFS(งานทั้งหมด!$D$5:$D$300,A14,งานทั้งหมด!$F$5:$F$300,"รอตรวจ") -> 0 | G14: =COUNTIFS(งานทั้งหมด!$D$5:$D$300,A14,งานทั้งหมด!$F$5:$F$300,"เสร็จแล้ว") -> 1 | H14: =COUNTIFS(งานทั้งหมด!$D$5:$D$300,A14,งานทั้งหมด!$M$5:$M$300,"เกินกำหนด") -> 0 | I14: =SUMIF(งานทั้งหมด!$D$5:$D$300,A14,งานทั้งหมด!$I$5:$I$300) -> 95 | J14: =SUMIF(งานทั้งหมด!$D$5:$D$300,A14,งานทั้งหมด!$J$5:$J$300) -> 44 | K14: =IFERROR(G14/C14,0) -> 0.25 | L14: =IFERROR(I14/J14,0) -> 2.1590909
A15: =ทีมงาน!B11 -> อรทัย | B15: =ทีมงาน!C11 -> Data Analyst | C15: =COUNTIF(งานทั้งหมด!$D$5:$D$300,A15) -> 4 | D15: =COUNTIFS(งานทั้งหมด!$D$5:$D$300,A15,งานทั้งหมด!$F$5:$F$300,"ยังไม่เริ่ม") -> 0 | E15: =COUNTIFS(งานทั้งหมด!$D$5:$D$300,A15,งานทั้งหมด!$F$5:$F$300,"กำลังดำเนินการ") -> 1 | F15: =COUNTIFS(งานทั้งหมด!$D$5:$D$300,A15,งานทั้งหมด!$F$5:$F$300,"รอตรวจ") -> 0 | G15: =COUNTIFS(งานทั้งหมด!$D$5:$D$300,A15,งานทั้งหมด!$F$5:$F$300,"เสร็จแล้ว") -> 3 | H15: =COUNTIFS(งานทั้งหมด!$D$5:$D$300,A15,งานทั้งหมด!$M$5:$M$300,"เกินกำหนด") -> 0 | I15: =SUMIF(งานทั้งหมด!$D$5:$D$300,A15,งานทั้งหมด!$I$5:$I$300) -> 27 | J15: =SUMIF(งานทั้งหมด!$D$5:$D$300,A15,งานทั้งหมด!$J$5:$J$300) -> 23 | K15: =IFERROR(G15/C15,0) -> 0.75 | L15: =IFERROR(I15/J15,0) -> 1.173913
A16: =ทีมงาน!B12 -> ชลธิชา | B16: =ทีมงาน!C12 -> SEO Specialist | C16: =COUNTIF(งานทั้งหมด!$D$5:$D$300,A16) -> 4 | D16: =COUNTIFS(งานทั้งหมด!$D$5:$D$300,A16,งานทั้งหมด!$F$5:$F$300,"ยังไม่เริ่ม") -> 1 | E16: =COUNTIFS(งานทั้งหมด!$D$5:$D$300,A16,งานทั้งหมด!$F$5:$F$300,"กำลังดำเนินการ") -> 1 | F16: =COUNTIFS(งานทั้งหมด!$D$5:$D$300,A16,งานทั้งหมด!$F$5:$F$300,"รอตรวจ") -> 1 | G16: =COUNTIFS(งานทั้งหมด!$D$5:$D$300,A16,งานทั้งหมด!$F$5:$F$300,"เสร็จแล้ว") -> 1 | H16: =COUNTIFS(งานทั้งหมด!$D$5:$D$300,A16,งานทั้งหมด!$M$5:$M$300,"เกินกำหนด") -> 1 | I16: =SUMIF(งานทั้งหมด!$D$5:$D$300,A16,งานทั้งหมด!$I$5:$I$300) -> 72 | J16: =SUMIF(งานทั้งหมด!$D$5:$D$300,A16,งานทั้งหมด!$J$5:$J$300) -> 38 | K16: =IFERROR(G16/C16,0) -> 0.25 | L16: =IFERROR(I16/J16,0) -> 1.8947368
A17: =ทีมงาน!B13 -> กมลชนก | B17: =ทีมงาน!C13 -> Social Media Executive | C17: =COUNTIF(งานทั้งหมด!$D$5:$D$300,A17) -> 4 | D17: =COUNTIFS(งานทั้งหมด!$D$5:$D$300,A17,งานทั้งหมด!$F$5:$F$300,"ยังไม่เริ่ม") -> 0 | E17: =COUNTIFS(งานทั้งหมด!$D$5:$D$300,A17,งานทั้งหมด!$F$5:$F$300,"กำลังดำเนินการ") -> 1 | F17: =COUNTIFS(งานทั้งหมด!$D$5:$D$300,A17,งานทั้งหมด!$F$5:$F$300,"รอตรวจ") -> 2 | G17: =COUNTIFS(งานทั้งหมด!$D$5:$D$300,A17,งานทั้งหมด!$F$5:$F$300,"เสร็จแล้ว") -> 0 | H17: =COUNTIFS(งานทั้งหมด!$D$5:$D$300,A17,งานทั้งหมด!$M$5:$M$300,"เกินกำหนด") -> 1 | I17: =SUMIF(งานทั้งหมด!$D$5:$D$300,A17,งานทั้งหมด!$I$5:$I$300) -> 38 | J17: =SUMIF(งานทั้งหมด!$D$5:$D$300,A17,งานทั้งหมด!$J$5:$J$300) -> 26 | K17: =IFERROR(G17/C17,0) -> 0 | L17: =IFERROR(I17/J17,0) -> 1.4615385
A18: =ทีมงาน!B14 -> รัชนก | B18: =ทีมงาน!C14 -> Account Executive | C18: =COUNTIF(งานทั้งหมด!$D$5:$D$300,A18) -> 2 | D18: =COUNTIFS(งานทั้งหมด!$D$5:$D$300,A18,งานทั้งหมด!$F$5:$F$300,"ยังไม่เริ่ม") -> 0 | E18: =COUNTIFS(งานทั้งหมด!$D$5:$D$300,A18,งานทั้งหมด!$F$5:$F$300,"กำลังดำเนินการ") -> 1 | F18: =COUNTIFS(งานทั้งหมด!$D$5:$D$300,A18,งานทั้งหมด!$F$5:$F$300,"รอตรวจ") -> 0 | G18: =COUNTIFS(งานทั้งหมด!$D$5:$D$300,A18,งานทั้งหมด!$F$5:$F$300,"เสร็จแล้ว") -> 1 | H18: =COUNTIFS(งานทั้งหมด!$D$5:$D$300,A18,งานทั้งหมด!$M$5:$M$300,"เกินกำหนด") -> 0 | I18: =SUMIF(งานทั้งหมด!$D$5:$D$300,A18,งานทั้งหมด!$I$5:$I$300) -> 14 | J18: =SUMIF(งานทั้งหมด!$D$5:$D$300,A18,งานทั้งหมด!$J$5:$J$300) -> 11 | K18: =IFERROR(G18/C18,0) -> 0.5 | L18: =IFERROR(I18/J18,0) -> 1.2727273
A19: =ทีมงาน!B15 -> ภัทรพล | B19: =ทีมงาน!C15 -> Junior Graphic Designer | C19: =COUNTIF(งานทั้งหมด!$D$5:$D$300,A19) -> 2 | D19: =COUNTIFS(งานทั้งหมด!$D$5:$D$300,A19,งานทั้งหมด!$F$5:$F$300,"ยังไม่เริ่ม") -> 1 | E19: =COUNTIFS(งานทั้งหมด!$D$5:$D$300,A19,งานทั้งหมด!$F$5:$F$300,"กำลังดำเนินการ") -> 1 | F19: =COUNTIFS(งานทั้งหมด!$D$5:$D$300,A19,งานทั้งหมด!$F$5:$F$300,"รอตรวจ") -> 0 | G19: =COUNTIFS(งานทั้งหมด!$D$5:$D$300,A19,งานทั้งหมด!$F$5:$F$300,"เสร็จแล้ว") -> 0 | H19: =COUNTIFS(งานทั้งหมด!$D$5:$D$300,A19,งานทั้งหมด!$M$5:$M$300,"เกินกำหนด") -> 0 | I19: =SUMIF(งานทั้งหมด!$D$5:$D$300,A19,งานทั้งหมด!$I$5:$I$300) -> 12 | J19: =SUMIF(งานทั้งหมด!$D$5:$D$300,A19,งานทั้งหมด!$J$5:$J$300) -> 2 | K19: =IFERROR(G19/C19,0) -> 0 | L19: =IFERROR(I19/J19,0) -> 6
A20: รวมทั้งทีม | C20: =SUM(C9:C19) -> 46 | D20: =SUM(D9:D19) -> 11 | E20: =SUM(E9:E19) -> 15 | F20: =SUM(F9:F19) -> 5 | G20: =SUM(G9:G19) -> 14 | H20: =SUM(H9:H19) -> 5 | I20: =SUM(I9:I19) -> 567 | J20: =SUM(J9:J19) -> 329 | K20: =IFERROR(G20/C20,0) -> 0.30434783 | L20: =IFERROR(I20/J20,0) -> 1.7234043
A22: หมายเหตุการใช้งาน
A23: 1. เพิ่มงานใหม่ได้ที่ชีต 'งานทั้งหมด' ต่อท้ายแถวสุดท้าย สูตรในคอลัมน์ L และ M จะคำนวณให้อัตโนมัติ
A24: 2. ผู้รับผิดชอบเลือกจากรายชื่อในชีต 'ทีมงาน' (ดรอปดาวน์) ทั้งหมด 11 คน (หัวหน้า 1 + ลูกน้อง 10)
A25: 3. 'เกินกำหนด' = ยังไม่เสร็จและวันที่ปัจจุบันเลยกำหนดเสร็จแล้ว / 'ใกล้ครบกำหนด' = เหลือไม่เกิน 3 วัน
A26: 4. ข้อมูลทั้งหมดเป็นตัวอย่างสมมติ ชื่อและลูกค้าไม่ใช่บุคคลหรือบริษัทจริง

Sheet ทีมงาน
A1: รายชื่อทีมงาน — ทีมการตลาดดิจิทัล
A2: หัวหน้า 1 คน / ลูกน้อง 10 คน (ข้อมูลตัวอย่าง)
A4: ลำดับ | B4: ชื่อ | C4: ตำแหน่ง | D4: หน้าที่หลัก | E4: อีเมล | F4: วันเริ่มงาน | G4: ระดับ
A5: 1 | B5: วิภา | C5: หัวหน้าทีม (Team Lead) | D5: วางแผนงาน ติดตามความคืบหน้า รีวิวงานก่อนส่งลูกค้า | E5: vipa@example.com | F5: 44270 | G5: ระดับ 5
A6: 2 | B6: ณัฐวุฒิ | C6: Senior Graphic Designer | D6: ออกแบบ Key Visual สื่อโฆษณา และ Banner | E6: nattawut@example.com | F6: 44713 | G6: ระดับ 4
A7: 3 | B7: นภา | C7: Content Writer | D7: เขียนคอนเทนต์ Social Media และคำบรรยายสินค้า | E7: napa@example.com | F7: 44816 | G7: ระดับ 3
A8: 4 | B8: ปิยะ | C8: Photographer & Video Producer | D8: ถ่ายภาพ ถ่ายวิดีโอ และวางแผนคอนเทนต์วิดีโอ | E8: piya@example.com | F8: 44501 | G8: ระดับ 4
A9: 5 | B9: ธนพล | C9: Performance Marketer | D9: ดูแลแคมเปญ Facebook / Google Ads และวิเคราะห์ผล | E9: thanaphon@example.com | F9: 44977 | G9: ระดับ 3
A10: 6 | B10: ศุภกิจ | C10: Web Developer | D10: พัฒนาและดูแลเว็บไซต์ Landing Page และระบบ Tracking | E10: supakit@example.com | F10: 44655 | G10: ระดับ 4
A11: 7 | B11: อรทัย | C11: Data Analyst | D11: ตั้งค่า Analytics และจัดทำรายงานยอดขาย | E11: orathai@example.com | F11: 45117 | G11: ระดับ 3
A12: 8 | B12: ชลธิชา | C12: SEO Specialist | D12: วิจัยคีย์เวิร์ด ทำ SEO และเขียนบทความ | E12: cholticha@example.com | F12: 44942 | G12: ระดับ 3
A13: 9 | B13: กมลชนก | C13: Social Media Executive | D13: ดูแล Fanpage, LINE OA และตัดต่อวิดีโอสั้น | E13: kamolchanok@example.com | F13: 45418 | G13: ระดับ 2
A14: 10 | B14: รัชนก | C14: Account Executive | D14: ประสานงานลูกค้า Influencer และติดตามสัญญา | E14: ratchanok@example.com | F14: 45523 | G14: ระดับ 2
A15: 11 | B15: ภัทรพล | C15: Junior Graphic Designer | D15: ออกแบบ Infographic และตัดต่อ Reels | E15: phatthaphon@example.com | F15: 45663 | G15: ระดับ 1

Sheet งานทั้งหมด
A1: งานทั้งหมด — Project Tracking
A2: กรอกเฉพาะคอลัมน์สีขาว ส่วนคอลัมน์ L และ M คำนวณอัตโนมัติ
A4: รหัสงาน | B4: ลูกค้า / โครงการ | C4: ชื่องาน | D4: ผู้รับผิดชอบ | E4: ความสำคัญ | F4: สถานะ | G4: วันเริ่ม | H4: กำหนดเสร็จ | I4: ชั่วโมงประเมิน | J4: ชั่วโมงจริง | K4: % ความคืบหน้า | L4: วันคงเหลือ | M4: สถานะเวลา | N4: หมายเหตุ
A5: T-001 | B5: บ้านสวน คาเฟ่ | C5: ออกแบบ Key Visual แคมเปญปีใหม่ | D5: ณัฐวุฒิ | E5: สูง | F5: เสร็จแล้ว | G5: 46296 | H5: 46305 | I5: 16 | J5: 18 | K5: 1 | L5: =IF(F5="เสร็จแล้ว","",H5-TODAY()) | M5: =IF(F5="เสร็จแล้ว","เสร็จแล้ว",IF(H5<TODAY(),"เกินกำหนด",IF(H5-TODAY()<=3,"ใกล้ครบกำหนด","ปกติ"))) -> เสร็จแล้ว | N5: ลูกค้าอนุมัติแล้ว
A6: T-002 | B6: บ้านสวน คาเฟ่ | C6: เขียนคอนเทนต์ Facebook 12 โพสต์ เดือนตุลาคม | D6: นภา | E6: กลาง | F6: เสร็จแล้ว | G6: 46296 | H6: 46310 | I6: 12 | J6: 11 | K6: 1 | L6: =IF(F6="เสร็จแล้ว","",H6-TODAY()) | M6: =IF(F6="เสร็จแล้ว","เสร็จแล้ว",IF(H6<TODAY(),"เกินกำหนด",IF(H6-TODAY()<=3,"ใกล้ครบกำหนด","ปกติ"))) -> เสร็จแล้ว
A7: T-003 | B7: บ้านสวน คาเฟ่ | C7: ถ่ายภาพสินค้าเมนูฤดูหนาว | D7: ปิยะ | E7: กลาง | F7: เสร็จแล้ว | G7: 46300 | H7: 46307 | I7: 10 | J7: 12 | K7: 1 | L7: =IF(F7="เสร็จแล้ว","",H7-TODAY()) | M7: =IF(F7="เสร็จแล้ว","เสร็จแล้ว",IF(H7<TODAY(),"เกินกำหนด",IF(H7-TODAY()<=3,"ใกล้ครบกำหนด","ปกติ"))) -> เสร็จแล้ว | N7: ใช้เวลาเพิ่มจากการจัดแสง
A8: T-004 | B8: บ้านสวน คาเฟ่ | C8: ตั้งค่าแคมเปญ Facebook Ads งบ 15,000 บาท | D8: ธนพล | E8: สูง | F8: กำลังดำเนินการ | G8: 46315 | H8: 46322 | I8: 6 | J8: 5 | K8: 0.7 | L8: =IF(F8="เสร็จแล้ว","",H8-TODAY()) -> -2 | M8: =IF(F8="เสร็จแล้ว","เสร็จแล้ว",IF(H8<TODAY(),"เกินกำหนด",IF(H8-TODAY()<=3,"ใกล้ครบกำหนด","ปกติ"))) -> เกินกำหนด | N8: CPC ยังสูงกว่าเป้า 20%
A9: T-005 | B9: บ้านสวน คาเฟ่ | C9: ทำ Story Highlight และ Cover ใหม่ | D9: ปิยะ | E9: ต่ำ | F9: เสร็จแล้ว | G9: 46310 | H9: 46315 | I9: 4 | J9: 4 | K9: 1 | L9: =IF(F9="เสร็จแล้ว","",H9-TODAY()) | M9: =IF(F9="เสร็จแล้ว","เสร็จแล้ว",IF(H9<TODAY(),"เกินกำหนด",IF(H9-TODAY()<=3,"ใกล้ครบกำหนด","ปกติ"))) -> เสร็จแล้ว
A10: T-006 | B10: บ้านสวน คาเฟ่ | C10: เตรียมคอนเทนต์รับเทศกาลปีใหม่ 2570 | D10: นภา | E10: สูง | F10: ยังไม่เริ่ม | G10: 46329 | H10: 46346 | I10: 14 | J10: 0 | K10: 0 | L10: =IF(F10="เสร็จแล้ว","",H10-TODAY()) -> 22 | M10: =IF(F10="เสร็จแล้ว","เสร็จแล้ว",IF(H10<TODAY(),"เกินกำหนด",IF(H10-TODAY()<=3,"ใกล้ครบกำหนด","ปกติ"))) -> ปกติ | N10: รอ Brief จากลูกค้า
A11: T-007 | B11: โรงแรม ริมน้ำ | C11: ทำเว็บไซต์หน้าจองห้องพักรูปแบบใหม่ | D11: ศุภกิจ | E11: สูง | F11: กำลังดำเนินการ | G11: 46303 | H11: 46341 | I11: 60 | J11: 38 | K11: 0.6 | L11: =IF(F11="เสร็จแล้ว","",H11-TODAY()) -> 17 | M11: =IF(F11="เสร็จแล้ว","เสร็จแล้ว",IF(H11<TODAY(),"เกินกำหนด",IF(H11-TODAY()<=3,"ใกล้ครบกำหนด","ปกติ"))) -> ปกติ | N11: ทำ Responsive เสร็จแล้ว รอ Payment Gateway
A12: T-008 | B12: โรงแรม ริมน้ำ | C12: วิเคราะห์คู่แข่ง 5 โรงแรมในพื้นที่เชียงใหม่ | D12: อรทัย | E12: กลาง | F12: เสร็จแล้ว | G12: 46298 | H12: 46309 | I12: 8 | J12: 9 | K12: 1 | L12: =IF(F12="เสร็จแล้ว","",H12-TODAY()) | M12: =IF(F12="เสร็จแล้ว","เสร็จแล้ว",IF(H12<TODAY(),"เกินกำหนด",IF(H12-TODAY()<=3,"ใกล้ครบกำหนด","ปกติ"))) -> เสร็จแล้ว
A13: T-009 | B13: โรงแรม ริมน้ำ | C13: ทำ SEO คีย์เวิร์ด "ที่พักริมน้ำ" 20 บทความ | D13: ชลธิชา | E13: สูง | F13: กำลังดำเนินการ | G13: 46307 | H13: 46331 | I13: 40 | J13: 22 | K13: 0.55 | L13: =IF(F13="เสร็จแล้ว","",H13-TODAY()) -> 7 | M13: =IF(F13="เสร็จแล้ว","เสร็จแล้ว",IF(H13<TODAY(),"เกินกำหนด",IF(H13-TODAY()<=3,"ใกล้ครบกำหนด","ปกติ"))) -> ปกติ
A14: T-010 | B14: โรงแรม ริมน้ำ | C14: ตัดต่อวิดีโอแนะนำห้องพัก 60 วินาที | D14: กมลชนก | E14: กลาง | F14: รอตรวจ | G14: 46313 | H14: 46321 | I14: 12 | J14: 13 | K14: 0.9 | L14: =IF(F14="เสร็จแล้ว","",H14-TODAY()) -> -3 | M14: =IF(F14="เสร็จแล้ว","เสร็จแล้ว",IF(H14<TODAY(),"เกินกำหนด",IF(H14-TODAY()<=3,"ใกล้ครบกำหนด","ปกติ"))) -> เกินกำหนด | N14: ส่งให้หัวหน้ารีวิว
A15: T-011 | B15: โรงแรม ริมน้ำ | C15: รายงานผลแคมเปญประจำเดือน ก.ย. | D15: วิภา | E15: ต่ำ | F15: เสร็จแล้ว | G15: 46296 | H15: 46302 | I15: 4 | J15: 4 | K15: 1 | L15: =IF(F15="เสร็จแล้ว","",H15-TODAY()) | M15: =IF(F15="เสร็จแล้ว","เสร็จแล้ว",IF(H15<TODAY(),"เกินกำหนด",IF(H15-TODAY()<=3,"ใกล้ครบกำหนด","ปกติ"))) -> เสร็จแล้ว
A16: T-012 | B16: โรงแรม ริมน้ำ | C16: ทำรายงาน SEO Monthly ก.ย. | D16: ชลธิชา | E16: กลาง | F16: เสร็จแล้ว | G16: 46297 | H16: 46303 | I16: 4 | J16: 5 | K16: 1 | L16: =IF(F16="เสร็จแล้ว","",H16-TODAY()) | M16: =IF(F16="เสร็จแล้ว","เสร็จแล้ว",IF(H16<TODAY(),"เกินกำหนด",IF(H16-TODAY()<=3,"ใกล้ครบกำหนด","ปกติ"))) -> เสร็จแล้ว
A17: T-013 | B17: โรงแรม ริมน้ำ | C17: ทดสอบความเร็วเว็บและแก้ Core Web Vitals | D17: ศุภกิจ | E17: สูง | F17: ยังไม่เริ่ม | G17: 46336 | H17: 46350 | I17: 10 | J17: 0 | K17: 0 | L17: =IF(F17="เสร็จแล้ว","",H17-TODAY()) -> 26 | M17: =IF(F17="เสร็จแล้ว","เสร็จแล้ว",IF(H17<TODAY(),"เกินกำหนด",IF(H17-TODAY()<=3,"ใกล้ครบกำหนด","ปกติ"))) -> ปกติ | N17: รอทีมเว็บปิดงานหน้าจอง
A18: T-014 | B18: โรงแรม ริมน้ำ | C18: ประสานงานรีวิวจากลูกค้าเข้าพัก 10 ราย | D18: รัชนก | E18: กลาง | F18: กำลังดำเนินการ | G18: 46315 | H18: 46327 | I18: 8 | J18: 4 | K18: 0.5 | L18: =IF(F18="เสร็จแล้ว","",H18-TODAY()) -> 3 | M18: =IF(F18="เสร็จแล้ว","เสร็จแล้ว",IF(H18<TODAY(),"เกินกำหนด",IF(H18-TODAY()<=3,"ใกล้ครบกำหนด","ปกติ"))) -> ใกล้ครบกำหนด
A19: T-015 | B19: คลินิกผิวหน้า ลูมิเน่ | C19: ออกแบบโบรชัวร์บริการ 3 หน้า | D19: ณัฐวุฒิ | E19: กลาง | F19: กำลังดำเนินการ | G19: 46317 | H19: 46327 | I19: 10 | J19: 6 | K19: 0.5 | L19: =IF(F19="เสร็จแล้ว","",H19-TODAY()) -> 3 | M19: =IF(F19="เสร็จแล้ว","เสร็จแล้ว",IF(H19<TODAY(),"เกินกำหนด",IF(H19-TODAY()<=3,"ใกล้ครบกำหนด","ปกติ"))) -> ใกล้ครบกำหนด
A20: T-016 | B20: คลินิกผิวหน้า ลูมิเน่ | C20: วางแผนคอนเทนต์ TikTok 8 คลิป | D20: ปิยะ | E20: สูง | F20: กำลังดำเนินการ | G20: 46314 | H20: 46323 | I20: 16 | J20: 14 | K20: 0.8 | L20: =IF(F20="เสร็จแล้ว","",H20-TODAY()) -> -1 | M20: =IF(F20="เสร็จแล้ว","เสร็จแล้ว",IF(H20<TODAY(),"เกินกำหนด",IF(H20-TODAY()<=3,"ใกล้ครบกำหนด","ปกติ"))) -> เกินกำหนด | N20: เหลือถ่ายอีก 2 คลิป
A21: T-017 | B21: คลินิกผิวหน้า ลูมิเน่ | C21: ตอบคอมเมนต์และ Inbox ประจำสัปดาห์ | D21: นภา | E21: กลาง | F21: กำลังดำเนินการ | G21: 46296 | H21: 46356 | I21: 30 | J21: 18 | K21: 0.6 | L21: =IF(F21="เสร็จแล้ว","",H21-TODAY()) -> 32 | M21: =IF(F21="เสร็จแล้ว","เสร็จแล้ว",IF(H21<TODAY(),"เกินกำหนด",IF(H21-TODAY()<=3,"ใกล้ครบกำหนด","ปกติ"))) -> ปกติ | N21: งานต่อเนื่องรายสัปดาห์
A22: T-018 | B22: คลินิกผิวหน้า ลูมิเน่ | C22: ทำ Landing Page แคมเปญฟรีค่าปรึกษา | D22: ศุภกิจ | E22: สูง | F22: ยังไม่เริ่ม | G22: 46328 | H22: 46336 | I22: 20 | J22: 0 | K22: 0 | L22: =IF(F22="เสร็จแล้ว","",H22-TODAY()) -> 12 | M22: =IF(F22="เสร็จแล้ว","เสร็จแล้ว",IF(H22<TODAY(),"เกินกำหนด",IF(H22-TODAY()<=3,"ใกล้ครบกำหนด","ปกติ"))) -> ปกติ
A23: T-019 | B23: คลินิกผิวหน้า ลูมิเน่ | C23: ตั้งระบบติดตาม Lead จากฟอร์มเว็บ | D23: ธนพล | E23: กลาง | F23: ยังไม่เริ่ม | G23: 46331 | H23: 46340 | I23: 12 | J23: 0 | K23: 0 | L23: =IF(F23="เสร็จแล้ว","",H23-TODAY()) -> 16 | M23: =IF(F23="เสร็จแล้ว","เสร็จแล้ว",IF(H23<TODAY(),"เกินกำหนด",IF(H23-TODAY()<=3,"ใกล้ครบกำหนด","ปกติ"))) -> ปกติ
A24: T-020 | B24: คลินิกผิวหน้า ลูมิเน่ | C24: ตรวจสอบ Pixel และ Conversion | D24: ธนพล | E24: กลาง | F24: เสร็จแล้ว | G24: 46304 | H24: 46308 | I24: 5 | J24: 4 | K24: 1 | L24: =IF(F24="เสร็จแล้ว","",H24-TODAY()) | M24: =IF(F24="เสร็จแล้ว","เสร็จแล้ว",IF(H24<TODAY(),"เกินกำหนด",IF(H24-TODAY()<=3,"ใกล้ครบกำหนด","ปกติ"))) -> เสร็จแล้ว
A25: T-021 | B25: แบรนด์เครื่องสำอาง ไพร์ม | C25: ถ่าย Product Shoot ชุด Serum ใหม่ | D25: ปิยะ | E25: สูง | F25: เสร็จแล้ว | G25: 46301 | H25: 46311 | I25: 14 | J25: 15 | K25: 1 | L25: =IF(F25="เสร็จแล้ว","",H25-TODAY()) | M25: =IF(F25="เสร็จแล้ว","เสร็จแล้ว",IF(H25<TODAY(),"เกินกำหนด",IF(H25-TODAY()<=3,"ใกล้ครบกำหนด","ปกติ"))) -> เสร็จแล้ว
A26: T-022 | B26: แบรนด์เครื่องสำอาง ไพร์ม | C26: ออกแบบ Banner Shopee 10 ชิ้น | D26: ณัฐวุฒิ | E26: สูง | F26: รอตรวจ | G26: 46315 | H26: 46323 | I26: 14 | J26: 12 | K26: 0.95 | L26: =IF(F26="เสร็จแล้ว","",H26-TODAY()) -> -1 | M26: =IF(F26="เสร็จแล้ว","เสร็จแล้ว",IF(H26<TODAY(),"เกินกำหนด",IF(H26-TODAY()<=3,"ใกล้ครบกำหนด","ปกติ"))) -> เกินกำหนด
A27: T-023 | B27: แบรนด์เครื่องสำอาง ไพร์ม | C27: เขียนคำบรรยายสินค้า 25 รายการ | D27: นภา | E27: กลาง | F27: กำลังดำเนินการ | G27: 46310 | H27: 46329 | I27: 20 | J27: 9 | K27: 0.4 | L27: =IF(F27="เสร็จแล้ว","",H27-TODAY()) -> 5 | M27: =IF(F27="เสร็จแล้ว","เสร็จแล้ว",IF(H27<TODAY(),"เกินกำหนด",IF(H27-TODAY()<=3,"ใกล้ครบกำหนด","ปกติ"))) -> ปกติ
A28: T-024 | B28: แบรนด์เครื่องสำอาง ไพร์ม | C28: ตั้งค่า Google Analytics 4 และ Event Tracking | D28: อรทัย | E28: สูง | F28: กำลังดำเนินการ | G28: 46316 | H28: 46330 | I28: 10 | J28: 4 | K28: 0.4 | L28: =IF(F28="เสร็จแล้ว","",H28-TODAY()) -> 6 | M28: =IF(F28="เสร็จแล้ว","เสร็จแล้ว",IF(H28<TODAY(),"เกินกำหนด",IF(H28-TODAY()<=3,"ใกล้ครบกำหนด","ปกติ"))) -> ปกติ
A29: T-025 | B29: แบรนด์เครื่องสำอาง ไพร์ม | C29: ทำรายงานยอดขายจาก Shopee และ Lazada | D29: อรทัย | E29: กลาง | F29: เสร็จแล้ว | G29: 46305 | H29: 46312 | I29: 6 | J29: 7 | K29: 1 | L29: =IF(F29="เสร็จแล้ว","",H29-TODAY()) | M29: =IF(F29="เสร็จแล้ว","เสร็จแล้ว",IF(H29<TODAY(),"เกินกำหนด",IF(H29-TODAY()<=3,"ใกล้ครบกำหนด","ปกติ"))) -> เสร็จแล้ว
A30: T-026 | B30: แบรนด์เครื่องสำอาง ไพร์ม | C30: ทำ Influencer Brief 5 คน | D30: วิภา | E30: สูง | F30: รอตรวจ | G30: 46319 | H30: 46325 | I30: 8 | J30: 7 | K30: 0.9 | L30: =IF(F30="เสร็จแล้ว","",H30-TODAY()) -> 1 | M30: =IF(F30="เสร็จแล้ว","เสร็จแล้ว",IF(H30<TODAY(),"เกินกำหนด",IF(H30-TODAY()<=3,"ใกล้ครบกำหนด","ปกติ"))) -> ใกล้ครบกำหนด
A31: T-027 | B31: แบรนด์เครื่องสำอาง ไพร์ม | C31: ติดต่อ Influencer และส่งสินค้าตัวอย่าง | D31: รัชนก | E31: สูง | F31: เสร็จแล้ว | G31: 46302 | H31: 46309 | I31: 6 | J31: 7 | K31: 1 | L31: =IF(F31="เสร็จแล้ว","",H31-TODAY()) | M31: =IF(F31="เสร็จแล้ว","เสร็จแล้ว",IF(H31<TODAY(),"เกินกำหนด",IF(H31-TODAY()<=3,"ใกล้ครบกำหนด","ปกติ"))) -> เสร็จแล้ว | N31: ส่งสินค้าครบ 5 ราย
A32: T-028 | B32: แบรนด์เครื่องสำอาง ไพร์ม | C32: ทำ Email Newsletter ฉบับตุลาคม | D32: กมลชนก | E32: กลาง | F32: รอตรวจ | G32: 46317 | H32: 46324 | I32: 6 | J32: 6 | K32: 0.9 | L32: =IF(F32="เสร็จแล้ว","",H32-TODAY()) -> 0 | M32: =IF(F32="เสร็จแล้ว","เสร็จแล้ว",IF(H32<TODAY(),"เกินกำหนด",IF(H32-TODAY()<=3,"ใกล้ครบกำหนด","ปกติ"))) -> ใกล้ครบกำหนด
A33: T-029 | B33: โรงเรียนซันไรส์ | C33: ออกแบบโปสเตอร์รับสมัครนักเรียนปี 2570 | D33: ณัฐวุฒิ | E33: สูง | F33: กำลังดำเนินการ | G33: 46318 | H33: 46332 | I33: 12 | J33: 5 | K33: 0.4 | L33: =IF(F33="เสร็จแล้ว","",H33-TODAY()) -> 8 | M33: =IF(F33="เสร็จแล้ว","เสร็จแล้ว",IF(H33<TODAY(),"เกินกำหนด",IF(H33-TODAY()<=3,"ใกล้ครบกำหนด","ปกติ"))) -> ปกติ
A34: T-030 | B34: โรงเรียนซันไรส์ | C34: ทำ Facebook Ads ช่วงรับสมัคร งบ 30,000 บาท | D34: ธนพล | E34: สูง | F34: ยังไม่เริ่ม | G34: 46327 | H34: 46346 | I34: 10 | J34: 0 | K34: 0 | L34: =IF(F34="เสร็จแล้ว","",H34-TODAY()) -> 22 | M34: =IF(F34="เสร็จแล้ว","เสร็จแล้ว",IF(H34<TODAY(),"เกินกำหนด",IF(H34-TODAY()<=3,"ใกล้ครบกำหนด","ปกติ"))) -> ปกติ | N34: รอโปสเตอร์เสร็จก่อน
A35: T-031 | B35: โรงเรียนซันไรส์ | C35: จัดทำแผน Open House Event | D35: วิภา | E35: กลาง | F35: กำลังดำเนินการ | G35: 46313 | H35: 46334 | I35: 16 | J35: 8 | K35: 0.5 | L35: =IF(F35="เสร็จแล้ว","",H35-TODAY()) -> 10 | M35: =IF(F35="เสร็จแล้ว","เสร็จแล้ว",IF(H35<TODAY(),"เกินกำหนด",IF(H35-TODAY()<=3,"ใกล้ครบกำหนด","ปกติ"))) -> ปกติ
A36: T-032 | B36: โรงเรียนซันไรส์ | C36: ถ่ายวิดีโอบรรยากาศห้องเรียนและกิจกรรม | D36: ปิยะ | E36: กลาง | F36: ยังไม่เริ่ม | G36: 46336 | H36: 46344 | I36: 14 | J36: 0 | K36: 0 | L36: =IF(F36="เสร็จแล้ว","",H36-TODAY()) -> 20 | M36: =IF(F36="เสร็จแล้ว","เสร็จแล้ว",IF(H36<TODAY(),"เกินกำหนด",IF(H36-TODAY()<=3,"ใกล้ครบกำหนด","ปกติ"))) -> ปกติ | N36: ต้องขออนุญาตผู้ปกครอง
A37: T-033 | B37: โรงเรียนซันไรส์ | C37: เขียนบทความ Blog 6 เรื่องการเลือกโรงเรียน | D37: ชลธิชา | E37: ต่ำ | F37: ยังไม่เริ่ม | G37: 46329 | H37: 46361 | I37: 18 | J37: 0 | K37: 0 | L37: =IF(F37="เสร็จแล้ว","",H37-TODAY()) -> 37 | M37: =IF(F37="เสร็จแล้ว","เสร็จแล้ว",IF(H37<TODAY(),"เกินกำหนด",IF(H37-TODAY()<=3,"ใกล้ครบกำหนด","ปกติ"))) -> ปกติ
A38: T-034 | B38: โรงเรียนซันไรส์ | C38: ทำ Infographic เปรียบเทียบหลักสูตร | D38: ภัทรพล | E38: กลาง | F38: กำลังดำเนินการ | G38: 46319 | H38: 46333 | I38: 6 | J38: 2 | K38: 0.3 | L38: =IF(F38="เสร็จแล้ว","",H38-TODAY()) -> 9 | M38: =IF(F38="เสร็จแล้ว","เสร็จแล้ว",IF(H38<TODAY(),"เกินกำหนด",IF(H38-TODAY()<=3,"ใกล้ครบกำหนด","ปกติ"))) -> ปกติ
A39: T-035 | B39: ครัวป้าจี๋ | C39: ทำเมนูรายการอาหารใหม่ 8 เมนู (ภาพ+ข้อความ) | D39: นภา | E39: กลาง | F39: เสร็จแล้ว | G39: 46297 | H39: 46304 | I39: 10 | J39: 10 | K39: 1 | L39: =IF(F39="เสร็จแล้ว","",H39-TODAY()) | M39: =IF(F39="เสร็จแล้ว","เสร็จแล้ว",IF(H39<TODAY(),"เกินกำหนด",IF(H39-TODAY()<=3,"ใกล้ครบกำหนด","ปกติ"))) -> เสร็จแล้ว
A40: T-036 | B40: ครัวป้าจี๋ | C40: ลงทะเบียน Google Business Profile และอัปเดตข้อมูล | D40: อรทัย | E40: ต่ำ | F40: เสร็จแล้ว | G40: 46299 | H40: 46301 | I40: 3 | J40: 3 | K40: 1 | L40: =IF(F40="เสร็จแล้ว","",H40-TODAY()) | M40: =IF(F40="เสร็จแล้ว","เสร็จแล้ว",IF(H40<TODAY(),"เกินกำหนด",IF(H40-TODAY()<=3,"ใกล้ครบกำหนด","ปกติ"))) -> เสร็จแล้ว
A41: T-037 | B41: ครัวป้าจี๋ | C41: ตั้งค่า LINE OA และ Rich Menu | D41: กมลชนก | E41: กลาง | F41: กำลังดำเนินการ | G41: 46320 | H41: 46328 | I41: 8 | J41: 4 | K41: 0.5 | L41: =IF(F41="เสร็จแล้ว","",H41-TODAY()) -> 4 | M41: =IF(F41="เสร็จแล้ว","เสร็จแล้ว",IF(H41<TODAY(),"เกินกำหนด",IF(H41-TODAY()<=3,"ใกล้ครบกำหนด","ปกติ"))) -> ปกติ
...
